Workbook

Sheet Sheet1
A1: Product | B1: Product Name | C1: Category | D1: Brand | E1: Price | F1: Stock | G1: total sale
A2: ------- | B2: -------------- | C2: ------------- | D2: ------------ | E2: ------- | F2: -------
A3: P1001 | B3: Laptop | C3: Electronics | D3: Dell | E3: 55000 | F3: 25 | G3: =(Table1[[#This Row],[Price]]*Table1[[#This Row],[Stock]]) -> 1375000
A4: P1002 | B4: Smartphone | C4: Electronics | D4: Samsung | E4: 32000 | F4: 40 | G4: =(Table1[[#This Row],[Price]]*Table1[[#This Row],[Stock]]) -> 1280000
A5: P1003 | B5: Headphones | C5: Electronics | D5: Sony | E5: 4500 | F5: 80 | G5: =(Table1[[#This Row],[Price]]*Table1[[#This Row],[Stock]]) -> 360000
A6: P1004 | B6: Keyboard | C6: Accessories | D6: Logitech | E6: 1800 | F6: 65 | G6: =(Table1[[#This Row],[Price]]*Table1[[#This Row],[Stock]]) -> 117000
A7: P1005 | B7: Mouse | C7: Accessories | D7: HP | E7: 900 | F7: 120 | G7: =(Table1[[#This Row],[Price]]*Table1[[#This Row],[Stock]]) -> 108000
A8: P1006 | B8: Printer | C8: Electronics | D8: Canon | E8: 12500 | F8: 18 | G8: =(Table1[[#This Row],[Price]]*Table1[[#This Row],[Stock]]) -> 225000
A9: P1007 | B9: Office Chair | C9: Furniture | D9: Green Soul | E9: 8500 | F9: 20 | G9: =(Table1[[#This Row],[Price]]*Table1[[#This Row],[Stock]]) -> 170000
A10: P1008 | B10: Office Desk | C10: Furniture | D10: IKEA | E10: 12000 | F10: 15 | G10: =(Table1[[#This Row],[Price]]*Table1[[#This Row],[Stock]]) -> 180000
A11: P1009 | B11: Monitor | C11: Electronics | D11: LG | E11: 16000 | F11: 30 | G11: =(Table1[[#This Row],[Price]]*Table1[[#This Row],[Stock]]) -> 480000
A12: P1010 | B12: Webcam | C12: Accessories | D12: Logitech | E12: 3500 | F12: 50 | G12: =(Table1[[#This Row],[Price]]*Table1[[#This Row],[Stock]]) -> 175000
A14: Task 1
A15: Find the Product Name for Product ID P1006.
A16: name | B16: id
A17: =INDEX(Table1[[#All],[Product Name]],MATCH(A8,Table1[[#All],[Product]])) -> Printer | B17: P1006
A19: Task 2
A20: Find the Price for Product ID P1008.
A21: price | B21: p id
A22: =INDEX(Table1[[#All],[Price]],MATCH(A10,Table1[[#All],[Product]])) -> 12000 | B22: p1008
A24: Task 3
A25: Find the Brand for Product ID P1003
A26: brand | B26: p id
A27: =INDEX(Table1[[#All],[Brand]],MATCH(A5,Table1[[#All],[Product]])) -> Sony | B27: P1003
A29: Task 4
A30: Find the Stock for Product ID P1005.
A31: STOCK | B31: P ID
A32: =INDEX(Table1[[#All],[Stock]],MATCH(A5,Table1[[#All],[Product]])) -> 80 | B32: P1005
A34: Task 5
A35: Find the Category for Product ID P1004.
A36: CATEGORY | B36: PID
A37: =INDEX(Table1[[#All],[Category]],MATCH(A6,Table1[[#All],[Product]])) -> Accessories | B37: P1004

Sheet Sheet2
A1: Customer | B1: Customer Name | C1: City | D1: State | E1: Gender
A2: -------- | B2: --------------- | C2: ----------- | D2: ---------------- | E2: --------
A3: C001 | B3: Amit Patel | C3: Ahmedabad | D3: Gujarat | E3: Male
A4: C002 | B4: Priya Shah | C4: Surat | D4: Gujarat | E4: Female
A5: C003 | B5: Rahul Mehta | C5: Mumbai | D5: Maharashtra | E5: Male
A6: C004 | B6: Sneha Joshi | C6: Pune | D6: Maharashtra | E6: Female
A7: C005 | B7: Arjun Singh | C7: Jaipur | D7: Rajasthan | E7: Male
A8: C006 | B8: Neha Verma | C8: Delhi | D8: Delhi | E8: Female
A9: C007 | B9: Rohan Gupta | C9: Indore | D9: Madhya Pradesh | E9: Male
A10: C008 | B10: Pooja Sharma | C10: Lucknow | D10: Uttar Pradesh | E10: Female
A11: C009 | B11: Karan Desai | C11: Vadodara | D11: Gujarat | E11: Male
A12: C010 | B12: Anjali Nair | C12: Kochi | D12: Kerala | E12: Female
A14: Task 6
A15: Find the Customer Name for C007.
A16: NAME | B16: ID
A17: =INDEX(Table4[[#All],[Customer Name]],MATCH(A9,Table4[[#All],[Customer]])) -> Rohan Gupta | B17: C007
A19: Task 7
A20: Find the City for C010.
A21: CITY | B21: PID
A22: =INDEX(Table4[[#All],[City]],MATCH(A12,Table4[[#All],[Customer]])) -> Kochi | B22: C010
A24: Task 8
A25: Find the State for C003.
A26: STATE | B26: PID
A27: =INDEX(Table4[[#All],[State]],MATCH(A5,Table4[[#All],[Customer]])) -> Maharashtra | B27: C003
A29: Task 9
A30: Find the Gender for C006.
A31: GENDER | B31: PID
A32: =INDEX(Table4[[#All],[Gender]],MATCH(A8,Table4[[#All],[Customer]])) -> Female | B32: COO6

Sheet Sheet3
A1: Store ID | B1: Store Name | C1: City | D1: State
A2: ---------- | B2: --------------- | C2: ----------- | D2: -------------
A3: S001 | B3: Alpha Store | C3: Ahmedabad | D3: Gujarat
A4: S002 | B4: Beta Store | C4: Surat | D4: Gujarat
A5: S003 | B5: Central Store | C5: Mumbai | D5: Maharashtra
A6: S004 | B6: Digital Hub | C6: Pune | D6: Maharashtra
A7: S005 | B7: Smart World | C7: Jaipur | D7: Rajasthan
A9: Task 10
A10: Find the Store Name for S003.
A11: STORE NAME | B11: PID
A12: =INDEX(Table2[[#All],[Store Name]],MATCH(A5,Table2[[#All],[Store ID]])) -> Central Store | B12: S003
A14: Task 11
A15: Find the Store City for S005.
A16: STORE CITY | B16: PID
A17: =INDEX(Table2[[#All],[City]],MATCH(A7,Table2[[#All],[Store ID]])) -> Jaipur | B17: s005
A19: Task 12
A20: Find the Store State for S002.
A21: stat | B21: id
A22: =INDEX(Table2[[#All],[State]],MATCH(A7,Table2[[#All],[Store ID]])) -> Rajasthan | B22: s005

Sheet Sheet4
A1: Sale ID | B1: Product ID | C1: Customer ID | D1: Quantity | E1: Date | F1: Store ID
A2: --------- | B2: ------------ | C2: ------------- | D2: ---------- | E2: ------------- | F2: ----------
A3: SA001 | B3: P1001 | C3: C001 | D3: 1 | E3: 46023 | F3: S001
A4: SA002 | B4: P1005 | C4: C002 | D4: 3 | E4: 46024 | F4: S002
A5: SA003 | B5: P1003 | C5: C003 | D5: 2 | E5: 46025 | F5: S003
A6: SA004 | B6: P1009 | C6: C004 | D6: 1 | E6: 46026 | F6: S004
A7: SA005 | B7: P1002 | C7: C005 | D7: 2 | E7: 46027 | F7: S005
A8: SA006 | B8: P1007 | C8: C006 | D8: 1 | E8: 46028 | F8: S001
A9: SA007 | B9: P1006 | C9: C007 | D9: 1 | E9: 46029 | F9: S002
A10: SA008 | B10: P1010 | C10: C008 | D10: 2 | E10: 46030 | F10: S003
A11: SA009 | B11: P1004 | C11: C009 | D11: 4 | E11: 46031 | F11: S004
A12: SA010 | B12: P1008 | C12: C010 | D12: 1 | E12: 46032 | F12: S005
A13: SA011 | B13: P1005 | C13: C001 | D13: 5 | E13: 46033 | F13: S001
A14: SA012 | B14: P1003 | C14: C002 | D14: 3 | E14: 46034 | F14: S002
... A17: SA015 | B17: P1002 | C17: C005 | D17: 1 | E17: 46037 | F17: S005
A19: Task 13
A20: Retrieve the Product Name for every Product ID in the Sales shee
A22: Product ID
A23: ------------
A24: P1001 | B24: =INDEX(Table1[[#All],[Product Name]],MATCH(A24,Table1[[#All],[Product]],0)) -> Laptop
A25: P1005 | B25: =INDEX(Table1[[#All],[Product Name]],MATCH(A25,Table1[[#All],[Product]],0)) -> Mouse
A26: P1003 | B26: =INDEX(Table1[[#All],[Product Name]],MATCH(A26,Table1[[#All],[Product]],0)) -> Headphones
A27: P1009 | B27: =INDEX(Table1[[#All],[Product Name]],MATCH(A27,Table1[[#All],[Product]],0)) -> Monitor
A28: P1002 | B28: =INDEX(Table1[[#All],[Product Name]],MATCH(A28,Table1[[#All],[Product]],0)) -> Smartphone
A29: P1007 | B29: =INDEX(Table1[[#All],[Product Name]],MATCH(A29,Table1[[#All],[Product]],0)) -> Office Chair
A30: P1006 | B30: =INDEX(Table1[[#All],[Product Name]],MATCH(A30,Table1[[#All],[Product]],0)) -> Printer
A31: P1010 | B31: =INDEX(Table1[[#All],[Product Name]],MATCH(A31,Table1[[#All],[Product]],0)) -> Webcam
A32: P1004 | B32: =INDEX(Table1[[#All],[Product Name]],MATCH(A32,Table1[[#All],[Product]],0)) -> Keyboard
A33: P1008 | B33: =INDEX(Table1[[#All],[Product Name]],MATCH(A33,Table1[[#All],[Product]],0)) -> Office Desk
A34: P1005 | B34: =INDEX(Table1[[#All],[Product Name]],MATCH(A34,Table1[[#All],[Product]],0)) -> Mouse
A35: P1003 | B35: =INDEX(Table1[[#All],[Product Name]],MATCH(A35,Table1[[#All],[Product]],0)) -> Headphones
... A38: P1002 | B38: =INDEX(Table1[[#All],[Product Name]],MATCH(A38,Table1[[#All],[Product]],0)) -> Smartphone
A40: Task 14
A41: Retrieve the Customer Name for every Customer ID in the Sales sheet.
A42: customer id | B42: name
A43: Customer
A44: --------
A45: C001 | B45: =INDEX(Table4[[#All],[Customer Name]],MATCH(Sheet4!A45,Table4[[#All],[Customer]])) -> Amit Patel
A46: C002 | B46: =INDEX(Table4[[#All],[Customer Name]],MATCH(Sheet4!A46,Table4[[#All],[Customer]])) -> Priya Shah
A47: C003 | B47: =INDEX(Table4[[#All],[Customer Name]],MATCH(Sheet4!A47,Table4[[#All],[Customer]])) -> Rahul Mehta
...

Sheet Sheet5
